<?xml version="1.0"?>
<robot xmlns:xacro="http://ros.org/wiki/xacro" >
    <xacro:macro name="wheel_xacro" params="wheel_name xyz">
            <!-- 机器人的IMU部件，惯性测量传感器 -->
        <link name="${wheel_name}_link">
            <visual>
                <!-- 沿着自己几何中心的偏移和旋转量 -->
                <origin xyz="0 0 0" rpy="1.57079 0 0"/>
                <!-- 几何形状 -->
                <geometry>
                    <cylinder length="0.04" radius="0.032"/>
                </geometry>
                <!-- 材质颜色 -->
                <material name="yellow">
                    <color rgba="1.0 1.0 0.0 0.8"/>
                </material>
            </visual>
            <!-- 碰撞描述 -->
            <collision>
                <origin xyz="0 0 0" rpy="1.57079 0 0"/>
                <geometry>
                    <cylinder length="0.04" radius="0.032"/>
                </geometry>
                <material name="yellow">
                    <color rgba="1.0 1.0 0.0 0.8"/>
                </material>
            </collision>
            <!-- 惯性描述 -->
            <xacro:cylinder_inertia m="0.05" r="0.032" h="0.04"/>
        </link>

        <!-- 机器人的关节,用于组成 -->
        <joint name="${wheel_name}_joint" type="continuous">
            <parent link="base_link"/>
            <child link="${wheel_name}_link"/>
            <origin xyz="${xyz}" rpy="0 0 0"/>
            <axis xyz="0 1 0"/>
        </joint>

        <gazebo reference="${wheel_name}_link">
            <!-- 摩擦系数 -->
            <mu1 value="20.0"/>
            <mu2 value="20.0"/>
            <!-- 弹簧系数 -->
            <kp value="100000000.0"/>
            <!-- 阻尼系数 -->
            <kd value="1.0"/>
            <!-- 颜色 -->
            <material>Gazebo/Yellow</material>
        </gazebo>

    </xacro:macro>
</robot>